[2024-04-06 08:47:59,092] torch.distributed.run: [WARNING] master_addr is only used for static rdzv_backend and when rdzv_endpoint is not specified.
/root/miniconda3/bin/python: can't open file '/root/autodl-tmp/nanoGPT/data/openwebtext/./train.py': [Errno 2] No such file or directory
/root/miniconda3/bin/python: can't open file '/root/autodl-tmp/nanoGPT/data/openwebtext/./train.py': [Errno 2] No such file or directory
/root/miniconda3/bin/python: can't open file '/root/autodl-tmp/nanoGPT/data/openwebtext/./train.py': [Errno 2] No such file or directory
/root/miniconda3/bin/python: can't open file '/root/autodl-tmp/nanoGPT/data/openwebtext/./train.py': [Errno 2] No such file or directory
[2024-04-06 08:48:04,271] torch.distributed.elastic.multiprocessing.api: [ERROR] failed (exitcode: 2) local_rank: 0 (pid: 204598) of binary: /root/miniconda3/bin/python
Traceback (most recent call last):
  File "/root/miniconda3/bin/torchrun", line 8, in <module>
    sys.exit(main())
  File "/root/miniconda3/lib/python3.10/site-packages/torch/distributed/elastic/multiprocessing/errors/__init__.py", line 346, in wrapper
    return f(*args, **kwargs)
  File "/root/miniconda3/lib/python3.10/site-packages/torch/distributed/run.py", line 806, in main
    run(args)
  File "/root/miniconda3/lib/python3.10/site-packages/torch/distributed/run.py", line 797, in run
    elastic_launch(
  File "/root/miniconda3/lib/python3.10/site-packages/torch/distributed/launcher/api.py", line 134, in __call__
    return launch_agent(self._config, self._entrypoint, list(args))
  File "/root/miniconda3/lib/python3.10/site-packages/torch/distributed/launcher/api.py", line 264, in launch_agent
    raise ChildFailedError(
torch.distributed.elastic.multiprocessing.errors.ChildFailedError: 
============================================================
./train.py FAILED
------------------------------------------------------------
Failures:
[1]:
  time      : 2024-04-06_08:48:04
  host      : autodl-container-59154cad17-4f920b8c
  rank      : 1 (local_rank: 1)
  exitcode  : 2 (pid: 204599)
  error_file: <N/A>
  traceback : To enable traceback see: https://pytorch.org/docs/stable/elastic/errors.html
[2]:
  time      : 2024-04-06_08:48:04
  host      : autodl-container-59154cad17-4f920b8c
  rank      : 2 (local_rank: 2)
  exitcode  : 2 (pid: 204600)
  error_file: <N/A>
  traceback : To enable traceback see: https://pytorch.org/docs/stable/elastic/errors.html
[3]:
  time      : 2024-04-06_08:48:04
  host      : autodl-container-59154cad17-4f920b8c
  rank      : 3 (local_rank: 3)
  exitcode  : 2 (pid: 204601)
  error_file: <N/A>
  traceback : To enable traceback see: https://pytorch.org/docs/stable/elastic/errors.html
------------------------------------------------------------
Root Cause (first observed failure):
[0]:
  time      : 2024-04-06_08:48:04
  host      : autodl-container-59154cad17-4f920b8c
  rank      : 0 (local_rank: 0)
  exitcode  : 2 (pid: 204598)
  error_file: <N/A>
  traceback : To enable traceback see: https://pytorch.org/docs/stable/elastic/errors.html
============================================================
[2024-04-06 08:48:55,379] torch.distributed.run: [WARNING] master_addr is only used for static rdzv_backend and when rdzv_endpoint is not specified.
/root/miniconda3/bin/python: can't open file '/root/autodl-tmp/nanoGPT/data/openwebtext/./train.py': [Errno 2] No such file or directory
/root/miniconda3/bin/python: can't open file '/root/autodl-tmp/nanoGPT/data/openwebtext/./train.py': [Errno 2] No such file or directory
/root/miniconda3/bin/python: can't open file '/root/autodl-tmp/nanoGPT/data/openwebtext/./train.py': [Errno 2] No such file or directory
/root/miniconda3/bin/python: can't open file '/root/autodl-tmp/nanoGPT/data/openwebtext/./train.py': [Errno 2] No such file or directory
[2024-04-06 08:49:00,407] torch.distributed.elastic.multiprocessing.api: [ERROR] failed (exitcode: 2) local_rank: 0 (pid: 204839) of binary: /root/miniconda3/bin/python
Traceback (most recent call last):
  File "/root/miniconda3/bin/torchrun", line 8, in <module>
    sys.exit(main())
  File "/root/miniconda3/lib/python3.10/site-packages/torch/distributed/elastic/multiprocessing/errors/__init__.py", line 346, in wrapper
    return f(*args, **kwargs)
  File "/root/miniconda3/lib/python3.10/site-packages/torch/distributed/run.py", line 806, in main
    run(args)
  File "/root/miniconda3/lib/python3.10/site-packages/torch/distributed/run.py", line 797, in run
    elastic_launch(
  File "/root/miniconda3/lib/python3.10/site-packages/torch/distributed/launcher/api.py", line 134, in __call__
    return launch_agent(self._config, self._entrypoint, list(args))
  File "/root/miniconda3/lib/python3.10/site-packages/torch/distributed/launcher/api.py", line 264, in launch_agent
    raise ChildFailedError(
torch.distributed.elastic.multiprocessing.errors.ChildFailedError: 
============================================================
./train.py FAILED
------------------------------------------------------------
Failures:
[1]:
  time      : 2024-04-06_08:49:00
  host      : autodl-container-59154cad17-4f920b8c
  rank      : 1 (local_rank: 1)
  exitcode  : 2 (pid: 204840)
  error_file: <N/A>
  traceback : To enable traceback see: https://pytorch.org/docs/stable/elastic/errors.html
[2]:
  time      : 2024-04-06_08:49:00
  host      : autodl-container-59154cad17-4f920b8c
  rank      : 2 (local_rank: 2)
  exitcode  : 2 (pid: 204841)
  error_file: <N/A>
  traceback : To enable traceback see: https://pytorch.org/docs/stable/elastic/errors.html
[3]:
  time      : 2024-04-06_08:49:00
  host      : autodl-container-59154cad17-4f920b8c
  rank      : 3 (local_rank: 3)
  exitcode  : 2 (pid: 204842)
  error_file: <N/A>
  traceback : To enable traceback see: https://pytorch.org/docs/stable/elastic/errors.html
------------------------------------------------------------
Root Cause (first observed failure):
[0]:
  time      : 2024-04-06_08:49:00
  host      : autodl-container-59154cad17-4f920b8c
  rank      : 0 (local_rank: 0)
  exitcode  : 2 (pid: 204839)
  error_file: <N/A>
  traceback : To enable traceback see: https://pytorch.org/docs/stable/elastic/errors.html
============================================================
